Workbook

Sheet 計算式
B1: eBay販売価格（USD） | L1: 仕入価格（税込・円） | V1: 実重量（g） | AF1: カテゴリNo
B2: 82.98 | L2: 5800 | V2: 1500 | AF2: 69528
B3: 長さ（cm） | H3: 幅（cm） | N3: 高さ（cm） | T3: 購入者送料（USD） | AB3: USD/JPY | AH3: 体積重量A（g） | AL3: 体積重量B（g）
B4: 20 | H4: 20 | N4: 20 | T4: 0 | AB4: ='設定'!B4 -> 158.158 | AH4: ='計算詳細'!F8 -> 1000 | AL4: ='計算詳細'!G8 -> 1600
B6: 配送方法 | F6: Zonos | R6: Zonos(関税対象外) | AD6: Zonos(EU)
B7: 利益 | F7: ='計算詳細'!M16 -> -335.59755 | R7: ='計算詳細'!N16 -> 389.40245 | AD7: ='計算詳細'!O16 -> 349.62345
B8: 還付込み | F8: ='計算詳細'!M20 -> 191.67518 | R8: ='計算詳細'!N20 -> 916.67518 | AD8: ='計算詳細'!O20 -> 876.89618
B9: 送料（円） | F9: ='計算詳細'!C16 -> 3726 | R9: ='計算詳細'!C16 -> 3726 | AD9: ='計算詳細'!D16 -> 3060
B11: 配送方法 | F11: エコノミー(US) | L11: エコノミー(EU) | R11: FedEx(US) | X11: FedEx(EU) | AD11: DHL(US) | AJ11: DHL(EU)
B12: 利益 | F12: ='計算詳細'!I13 -> -347.78155 | L12: ='計算詳細'!Q25 -> -1440.7815 | R12: ='計算詳細'!J13 -> -1790.7815 | X12: ='計算詳細'!Q27 -> -892.78155 | AD12: ='計算詳細'!K13 -> -2071.7815 | AJ12: ='計算詳細'!Q29 -> -2209.7815
B13: 還付込み | F13: ='計算詳細'!I14 -> 179.49118 | L13: ='計算詳細'!Q26 -> -913.50882 | R13: ='計算詳細'!J14 -> -1263.5088 | X13: ='計算詳細'!Q28 -> -365.50882 | AD13: ='計算詳細'!K14 -> -1544.5088 | AJ13: ='計算詳細'!Q30 -> -1682.5088
B14: 送料（円） | F14: ='エコノミー送料'!G6 -> 5106 | L14: ='エコノミー送料'!G5 -> 6199 | R14: ='計算詳細'!J16 -> 5362 | X14: =IF(ISNUMBER('設定'!B30),'設定'!B30,'FedEx 送料'!M3) -> 5084 | AD14: ='計算詳細'!K16 -> 4999 | AJ14: =IF(ISNUMBER('設定'!B31),'設定'!B31,'DHL 送料'!M6) -> 5533
B16: 配送方法 | G16: エアパケ(US) | N16: エアパケ(EU) | U16: EMS(US) | AB16: 印刷物書留 | AI16: 書状書留
B17: 利益 | G17: ='計算詳細'!C13 -> 1032.2185 | N17: ='計算詳細'!D13 -> 1698.2185 | U17: ='計算詳細'!E13 -> -1125.8407 | AB17: ='計算詳細'!F13 -> 1016.1593 | AI17: ='計算詳細'!G13 -> -99.840709
B18: 還付込み | G18: ='計算詳細'!C14 -> 1559.4912 | N18: ='計算詳細'!D14 -> 2225.4912 | U18: ='計算詳細'!E14 -> -598.56798 | AB18: ='計算詳細'!F14 -> 1543.432 | AI18: ='計算詳細'!G14 -> 427.43202
B19: 送料（円） | G19: ='計算詳細'!C16 -> 3726 | N19: ='計算詳細'!D16 -> 3060 | U19: ='計算詳細'!E16 -> 5940 | AB19: ='計算詳細'!F16 -> 3798 | AI19: ='計算詳細'!G16 -> 4914

Sheet カテゴリー手数料一覧
A1: カテゴリNoカウント | B1: =COUNTIF(B4:B2102,'計算詳細'!$F$4) -> 0 | C1: =COUNTIF(C4:C2102,'計算詳細'!$F$4) -> 0 | D1: =COUNTIF(D4:D2102,'計算詳細'!$F$4) -> 0 | E1: =COUNTIF(E4:E2102,'計算詳細'!$F$4) -> 0 | F1: =COUNTIF(F4:F2102,'計算詳細'!$F$4) -> 0 | G1: =COUNTIF(G4:G2102,'計算詳細'!$F$4) -> 0 | H1: =COUNTIF(H4:H2102,'計算詳細'!$F$4) -> 0 | I1: =COUNTIF(I4:I2102,'計算詳細'!$F$4) -> 0 | ... U1: =COUNTIF(U4:U2102,'計算詳細'!$F$4) -> 1
A2: 適用手数料 | B2: =IF(AND(ISNUMBER(B6),ISNUMBER(B7),'計算詳細'!$B$4>=B6),B7,IF('計算詳細'!$B$4>=B4,B5,B3)) -> 0.025 | C2: =C3 -> 0.05 | D2: =IF(AND(ISNUMBER(D6),ISNUMBER(D7),'計算詳細'!$B$4>=D6),D7,IF('計算詳細'!$B$4>=D4,D5,D3)) -> 0.067 | E2: =IF(AND(ISNUMBER(E6),ISNUMBER(E7),'計算詳細'!$B$4>=E6),E7,IF('計算詳細'!$B$4>=E4,E5,E3)) -> 0.0735 | F2: =F3 -> 0.07 | G2: =IF(AND(ISNUMBER(G6),ISNUMBER(G7),'計算詳細'!$B$4>=G6),G7,IF('計算詳細'!$B$4>=G4,G5,G3)) -> 0.075 | H2: =IF(AND(ISNUMBER(H6),ISNUMBER(H7),'計算詳細'!$B$4>=H6),H7,IF('計算詳細'!$B$4>=H4,H5,H3)) -> 0.09 | I2: =IF(AND(ISNUMBER(I6),ISNUMBER(I7),'計算詳細'!$B$4>=I6),I7,IF('計算詳細'!$B$4>=I4,I5,I3)) -> 0.0935 | J2: =IF(AND(ISNUMBER(J6),ISNUMBER(J7),'計算詳細'!$B$4>=J6),J7,IF('計算詳細'!$B$4>=J4,J5,J3)) -> 0.095 | K2: =IF(AND(ISNUMBER(K6),ISNUMBER(K7),'計算詳細'!$B$4>=K6),K7,IF('計算詳細'!$B$4>=K4,K5,K3)) -> 0.097 | L2: =IF(AND(ISNUMBER(L6),ISNUMBER(L7),'計算詳細'!$B$4>=L6),L7,IF('計算詳細'!$B$4>=L4,L5,L3)) -> 0.1035 | M2: =IF(AND(ISNUMBER(M6),ISNUMBER(M7),'計算詳細'!$B$4>=M6),M7,IF('計算詳細'!$B$4>=M4,M5,M3)) -> 0.115 | N2: =IF(AND(ISNUMBER(N6),ISNUMBER(N7),'計算詳細'!$B$4>=N6),N7,IF('計算詳細'!$B$4>=N4,N5,N3)) -> 0.1235 | ... U2: =IF(AND(ISNUMBER(U6),ISNUMBER(U7),'計算詳細'!$B$4>=U6),U7,IF('計算詳細'!$B$4>=U4,U5,U3)) -> 0.127
A3: ベース手数料 | B3: 0.025 | C3: 0.05 | D3: 0.067 | E3: 0.0735 | F3: 0.07 | G3: 0.075 | H3: 0.09 | I3: 0.0935 | J3: 0.095 | K3: 0.097 | L3: 0.1035 | M3: 0.115 | N3: 0.1235 | O3: 0.125 | P3: 0.127 | Q3: 0.13 | R3: 0.13 | S3: 0.153 | T3: 0.0935 | U3: 0.127
A4: 割引①(＄) | B4: 15000 | D4: 2500 | E4: 2500 | G4: 1500 | H4: 4000 | I4: 1000 | J4: 1000 | K4: 2500 | L4: 2500 | M4: 1000 | N4: 2500 | O4: 1000 | P4: 1000 | Q4: 2000 | R4: 5000 | S4: 2500 | T4: 2500 | U4: 2500
A5: 割引① | B5: 0.005 | D5: 0.0235 | E5: 0.0235 | G5: 0.05 | H5: 0.0235 | I5: 0.0235 | J5: 0.0235 | K5: 0.0235 | L5: 0.0235 | M5: 0.0235 | N5: 0.0235 | O5: 0.04 | P5: 0.0235 | Q5: 0.07 | R5: 0.07 | S5: 0.0235 | T5: 0.0235 | U5: 0.0235
A6: 割引②(＄) | G6: 10000 | O6: 5000
A7: 割引② | G7: 0.045 | O7: 0.03
B8: 95493 | C8: 262054 | D8: 41407 | E8: 1244 | F8: 15709 | G8: 34942 | H8: 149944 | I8: 169367 | J8: 175575 | K8: 21035 | L8: 182139 | M8: 179460 | N8: 259113 | O8: 10324 | P8: 177125 | Q8: 169291 | R8: 261986 | S8: 120869 | T8: 11725 | U8: 162925
B9: 97122 | C9: 262051 | D9: 22669 | E9: 179 | F9: 95672 | G9: 177656 | H9: 41109 | I9: 96370 | J9: 263048 | K9: 262 | L9: 182140 | M9: 179416 | N9: 259114 | O9: 260331 | P9: 177076 | R9: 262021 | S9: 29223 | T9: 119018 | U9: 162926
B10: 73120 | C10: 262056 | D10: 41415 | E10: 111418 | G10: 3361 | H10: 162224 | I10: 38642 | J10: 175573 | K10: 263 | L10: 182142 | M10: 179471 | N10: 259115 | O10: 260332 | P10: 177078 | R10: 261975 | S10: 45113 | T10: 151236 | U10: 162927
B11: 183952 | C11: 262052 | D11: 47067 | E11: 131511 | G11: 177657 | H11: 3430 | I11: 138857 | J11: 171111 | K11: 264 | L11: 182146 | M11: 43987 | N11: 259118 | O11: 260330 | P11: 177084 | R11: 261979 | S11: 381 | T11: 66694 | U11: 37909
B12: 259042 | C12: 262055 | D12: 33050 | E12: 56083 | G12: 39489 | H12: 3405 | I12: 38771 | J12: 50071 | K12: 265 | L12: 182143 | M12: 179427 | N12: 259117 | O12: 260329 | P12: 177077 | R12: 261988 | S12: 118254 | T12: 131487 | U12: 63516
B13: 97185 | C13: 262050 | D13: 41417 | E13: 175670 | G13: 166679 | H13: 172173 | I13: 38776 | J13: 175574 | K13: 30261 | L13: 182144 | M13: 179439 | N13: 259119 | O13: 260326 | P13: 177080 | R13: 261976 | S13: 45114 | T13: 185118 | U13: 162928
B14: 95495 | C14: 262053 | D14: 41412 | E14: 80053 | G14: 177652 | H14: 162134 | I14: 53908 | J14: 179680 | K14: 30262 | L14: 182145 | M14: 179424 | N14: 259120 | O14: 98624 | P14: 177081 | R14: 262004 | S14: 63821 | T14: 158816 | U14: 162929
B15: 61568 | D15: 41421 | E15: 177 | G15: 162134 | H15: 179531 | I15: 174122 | J15: 175576 | K15: 3461 | L15: 101554 | M15: 179455 | N15: 259123 | O15: 98625 | P15: 177085 | R15: 261983 | S15: 164028 | T15: 178896 | U15: 37910
B16: 97121 | D16: 46680 | E16: 171485 | G16: 139965 | H16: 535 | I16: 185017 | J16: 175577 | K16: 3462 | L16: 179014 | M16: 179414 | N16: 259122 | O16: 117039 | P16: 177079 | R16: 261982 | S16: 171273 | T16: 14935 | U16: 63517
B17: 25253 | D17: 41431 | E17: 1245 | G17: 180910 | H17: 3360 | I17: 184979 | J17: 180242 | K17: 3463 | L17: 75557 | M17: 179458 | N17: 259125 | O17: 165144 | P17: 177118 | R17: 261977 | S17: 1105 | T17: 29954 | U17: 63518
B18: 92152 | D18: 101974 | E18: 164 | G18: 177653 | H18: 149926 | I18: 184651 | J18: 124313 | K18: 3464 | L18: 41396 | M18: 179432 | N18: 259128 | O18: 57721 | P18: 177114 | R18: 261981 | S18: 52554 | T18: 175717 | U18: 4708
B19: 73155 | D19: 41423 | E19: 175669 | G19: 3360 | H19: 41087 | I19: 122188 | J19: 175572 | K19: 3470 | L19: 159943 | M19: 179446 | N19: 259129 | O19: 57720 | P19: 177115 | R19: 261974 | S19: 52473 | T19: 162044 | U19: 37912
B20: 73094 | D20: 7266 | E20: 131553 | G20: 34943 | H20: 149943 | I20: 169391 | K20: 3471 | L20: 64374 | M20: 179429 | N20: 259130 | O20: 57723 | P20: 177116 | R20: 261991 | S20: 69496 | T20: 29986 | U20: 37914
B21: 63924 | D21: 181220 | E21: 139971 | G21: 162133 | H21: 173605 | I21: 184978 | K21: 3472 | L21: 16215 | M21: 179442 | N21: 259131 | O21: 57715 | P21: 177119 | R21: 261993 | S21: 132975 | T21: 175705 | U21: 37916
B22: 95494 | D22: 41420 | E22: 106273 | G22: 178906 | H22: 173589 | I22: 179671 | K22: 3473 | L22: 159945 | M22: 180038 | N22: 259132 | O22: 57714 | P22: 177117 | R22: 261990 | S22: 309 | T22: 29990 | U22: 162933
B23: 73121 | D23: 101973 | E23: 170083 | H23: 162147 | I23: 138855 | K23: 3474 | L23: 620 | M23: 179454 | N23: 259133 | O23: 3937 | P23: 177120 | R23: 262016 | S23: 618 | T23: 175701 | U23: 162934
B24: 259041 | D24: 41406 | E24: 111422 | H24: 3447 | I24: 184625 | K24: 3475 | L24: 261874 | M24: 179480 | N24: 259134 | O24: 31387 | P24: 177106 | R24: 262010 | S24: 617 | T24: 170067 | U24: 162935
B25: 41492 | D25: 41414 | H25: 173631 | I25: 96371 | K25: 3476 | L25: 182141 | M25: 179417 | N25: 259105 | O25: 51020 | P25: 177107 | R25: 261999 | S25: 29792 | T25: 29991 | U25: 184487
B26: 97123 | D26: 41434 | H26: 173593 | I26: 169358 | K26: 3480 | L26: 261876 | M26: 179455 | N26: 259104 | O26: 93720 | P26: 177121 | R26: 261998 | S26: 176983 | T26: 29980 | U26: 37913
B27: 184249 | D27: 22966 | H27: 173648 | I27: 61012 | K27: 3481 | L27: 261875 | M27: 179463 | N27: 259106 | O27: 260328 | P27: 177101 | R27: 261997 | S27: 41676 | T27: 170066 | U27: 37915
B28: 26249 | D28: 41408 | H28: 173599 | I28: 174119 | K28: 3482 | L28: 159944 | M28: 179459 | N28: 259107 | O28: 98624 | P28: 177112 | R28: 261995 | S28: 171223 | T28: 167943 | U28: 162930
B29: 58178 | D29: 22671 | H29: 176961 | I29: 60999 | K29: 3485 | L29: 16216 | M29: 179452 | N29: 259109 | P29: 177113 | R29: 262005 | S29: 176984 | T29: 29993 | U29: 66637
B30: 58161 | D30: 33034 | H30: 168684 | I30: 169382 | K30: 3486 | L30: 16214 | M30: 34999 | N30: 259110 | P30: 177110 | R30: 262006 | S30: 261186 | T30: 162485 | U30: 162931
B31: 91953 | D31: 41424 | H31: 173620 | I31: 169389 | K31: 3489 | L31: 179015 | M31: 179481 | N31: 259111 | P31: 177109 | R31: 262008 | S31: 11442 | T31: 29970 | U31: 162932
B32: 177642 | D32: 4713 | H32: 11964 | I32: 184626 | K32: 3490 | L32: 39179 | M32: 179488 | N32: 259112 | P32: 177105 | R32: 262003 | S32: 11233 | T32: 172516 | U32: 1207
B33: 177643 | D33: 41418 | H33: 162152 | I33: 185012 | K33: 3494 | L33: 41404 | M33: 179436 | N33: 259124 | P33: 177102 | R33: 262002 | T33: 29965 | U33: 162936
B34: 258645 | D34: 22672 | H34: 3446 | I34: 185021 | K34: 3500 | L34: 101555 | M34: 179486 | N34: 259126 | P34: 177103 | R34: 262013 | T34: 162048 | U34: 167948
B35: 46697 | D35: 148648 | H35: 3448 | I35: 169368 | K35: 3505 | L35: 1288 | M35: 179418 | N35: 259127 | P35: 177104 | R35: 262015 | T35: 29983 | U35: 171170
B36: 97125 | D36: 101976 | H36: 173688 | I36: 258035 | K36: 3507 | L36: 64388 | M36: 179437 | N36: 259150 | P36: 177108 | R36: 262018 | T36: 169 | U36: 162937
D37: 41419 | H37: 167964 | I37: 169473 | K37: 3508 | L37: 182150 | M37: 179473 | N37: 259149 | P37: 261280 | R37: 262012 | T37: 162075 | U37: 63519
D38: 119544 | H38: 118376 | I38: 169374 | K38: 3509 | L38: 64604 | M38: 179444 | N38: 259148 | P38: 261282 | R38: 262017 | T38: 29985 | U38: 151721
D39: 41422 | H39: 41102 | I39: 174118 | K39: 3510 | L39: 50590 | M39: 179444 | N39: 259145 | P39: 261271 | R39: 262020 | T39: 29973 | U39: 112084
D40: 38072 | H40: 58511 | I40: 169375 | K40: 35284 | L40: 64605 | M40: 179489 | N40: 259146 | P40: 261268 | R40: 262009 | T40: 185053 | U40: 37917
...

Sheet 送料
A1: 国際エアパケットEU | E1: 割増金 | I1: 国際エアパケットUS | L1: 書状書留
B2: 100 | C2: 880 | E2: エンベロープ | F2: 0.1 | G2: 2300 | I2: 100 | J2: 1200 | L2: 50 | M2: 740
B3: 200 | C3: 1060 | F3: 0.5 | G3: 2300 | I3: 200 | J3: 1410 | L3: 100 | M3: 880
B4: 300 | C4: 1240 | E4: パック(pak) | F4: 0.1 | G4: 2800 | I4: 300 | J4: 1620 | L4: 250 | M4: 1180
B5: 400 | C5: 1420 | F5: 0.5 | G5: 2800 | I5: 400 | J5: 1830 | L5: 500 | M5: 1720
B6: 500 | C6: 1600 | F6: 1 | G6: 3300 | I6: 500 | J6: 2040 | L6: 1000 | M6: 3320
B7: 600 | C7: 1780 | F7: 1.5 | G7: 3800 | I7: 600 | J7: 2250 | L7: 2000 | M7: 5460
B8: 700 | C8: 1960 | F8: 2 | G8: 4200 | I8: 700 | J8: 2460
B9: 800 | C9: 2140 | F9: 2.5 | G9: 4700 | I9: 800 | J9: 2670
B10: 900 | C10: 2320 | E10: プライオリティ(IP) | F10: 0.1 | G10: 2800 | I10: 900 | J10: 2880
B11: 1000 | C11: 2500 | F11: 0.5 | G11: 2800 | I11: 1000 | J11: 3090
B12: 1100 | C12: 2680 | F12: 1 | G12: 3100 | I12: 1100 | J12: 3300
B13: 1200 | C13: 2860 | F13: 2 | G13: 3300 | I13: 1200 | J13: 3510
B14: 1300 | C14: 3040 | F14: 3 | G14: 4300 | I14: 1300 | J14: 3720
B15: 1400 | C15: 3220 | F15: 4 | G15: 4900 | I15: 1400 | J15: 3930
B16: 1500 | C16: 3400 | F16: 5 | G16: 6000 | I16: 1500 | J16: 4140
B17: 1600 | C17: 3580 | F17: 6 | G17: 7500 | I17: 1600 | J17: 4350
B18: 1700 | C18: 3760 | F18: 7 | G18: 7900 | I18: 1700 | J18: 4560
B19: 1800 | C19: 3940 | F19: 8 | G19: 8200 | I19: 1800 | J19: 4770
B20: 1900 | C20: 4120 | F20: 9 | G20: 8600 | I20: 1900 | J20: 4980
B21: 2000 | C21: 4300 | F21: 10 | G21: 11100 | I21: 2000 | J21: 5190
F22: 11 | G22: 11500
A23: EMS | B23: 500 | C23: 3900 | F23: 12 | G23: 11900
B24: 600 | C24: 4180 | F24: 13 | G24: 14300
B25: 700 | C25: 4460 | F25: 14 | G25: 14800
B26: 800 | C26: 4740 | F26: 15 | G26: 15300
B27: 900 | C27: 5020 | F27: 16 | G27: 18000
B28: 1000 | C28: 5300 | F28: 17 | G28: 18600
B29: 1250 | C29: 5990 | F29: 18 | G29: 19100
B30: 1500 | C30: 6600 | F30: 19 | G30: 19700
B31: 1750 | C31: 7290 | F31: 20 | G31: 20200
B32: 2000 | C32: 7900 | E32: エコノミー(IE) | F32: 0.1 | G32: 2700
B33: 2500 | C33: 9100 | F33: 0.5 | G33: 2700
B34: 3000 | C34: 10300 | F34: 1 | G34: 3000
B35: 3500 | C35: 11500 | F35: 2 | G35: 3200
B36: 4000 | C36: 12700 | F36: 3 | G36: 4200
B37: 4500 | C37: 13900 | F37: 4 | G37: 4800
B38: 5000 | C38: 15100 | F38: 5 | G38: 5900
B39: 5500 | C39: 16300 | F39: 6 | G39: 7400
B40: 6000 | C40: 17500 | F40: 7 | G40: 7700
...

Sheet エコノミー送料
B1: US Economy | H1: EU Economy
B2: 基本送料 | C2: ='計算詳細'!I16 -> 3599 | F2: US地域 | G2: 本土48州 | H2: 基本送料 | I2: =G4 -> 4919
B3: 燃油サーチャージ | C3: =IF(ISNUMBER(C2),ROUND(C2*$G$11,0),"") -> 522 | F3: EU配送先 | G3: ='設定'!B27 -> イタリア | H3: 燃油サーチャージ | I3: =IF(ISNUMBER(I2),ROUND(I2*$G$11,0),"") -> 713
B4: その他送料加算 | C4: =IF(ISNUMBER($G$6),$G$6-'計算詳細'!I8-C2-C3,"") -> 0 | F4: EU基本送料 | G4: {=IF('計算詳細'!D4<=0,"重量未入力",IF(MIN('計算詳細'!C8:E8)<=0,"サイズ未入力",IF('計算詳細'!Q4>150,"150 EUR超",IF(OR(MAX('計算詳細'!C8:E8)>120,SUM('計算詳細'!C8:E8)-MAX('計算詳細'!C8:E8)-MIN('計算詳細'!C8:E8)>IF('計算詳細'!Q1="DE",60,40),PRODUCT('計算詳細'!C8:E8)>180000),"発送不可",IF('計算詳細'!Q11>20000,"料金表上限超過",INDEX(L10:AL65,COUNTIF(K10:K65,"<"&'計算詳細'!Q11)+1,MATCH('計算詳細'!Q1,L9:AL9,0)))))))} -> 4919 | H4: その他送料加算 | I4: =IF(ISNUMBER($G$5),$G$5-'計算詳細'!Q21-I2-I3,"") -> 0
B5: 送料合計 | C5: =IF(ISNUMBER($G$6),$G$6-'計算詳細'!I8,"") -> 4121 | F5: EU全費用 | G5: =IF(ISNUMBER(G4),IF(ISNUMBER('計算詳細'!Q21),G4+ROUND(G4*$G$11,0)+IF(OR(MAX('計算詳細'!C8:E8)<15,SUM('計算詳細'!C8:E8)-MAX('計算詳細'!C8:E8)-MIN('計算詳細'!C8:E8)<11,MIN('計算詳細'!C8:E8)<1),$G$14,0)+$G$15*$G$16+$G$17+'計算詳細'!Q21,"関税未計算"),G4) -> 6199 | H5: 送料合計 | I5: =IF(ISNUMBER($G$5),$G$5-'計算詳細'!Q21,"") -> 5632
B6: 推定関税 | C6: ='計算詳細'!Q6 -> 725 | F6: US全費用 | G6: =IF(ISNUMBER('計算詳細'!I16),IF(ISNUMBER('計算詳細'!I8),'計算詳細'!I16+ROUND('計算詳細'!I16*$G$11,0)+IF(OR(MAX('計算詳細'!C8:E8)>55.88,PRODUCT('計算詳細'!C8:E8)>55000),$G$13,0)+$G$17+'計算詳細'!I8,"関税未計算"),'計算詳細'!I16) -> 5106 | H6: 推定関税 | I6: ='計算詳細'!Q5 -> 555
B7: 処理・通関費 | C7: =IF(ISNUMBER('計算詳細'!I8),'計算詳細'!I8-C6,"") -> 260 | F7: US基本送料 | G7: ='計算詳細'!I16 -> 3599 | H7: 処理・通関費 | I7: =IF(AND(ISNUMBER('計算詳細'!Q21),ISNUMBER('計算詳細'!Q5)),'計算詳細'!Q21-'計算詳細'!Q5,"") -> 12
B8: 発送費用合計 | C8: =IF(ISNUMBER($G$6),$G$6,"未計算") -> 5106 | F8: 適用重量（kg） | G8: ='計算詳細'!Q11/1000 -> 1.5 | H8: 発送費用合計 | I8: =IF(ISNUMBER($G$5),$G$5,"未計算") -> 6199
B9: 重量（kg） 最大 | C9: 重量（g） 最大 | D9: JPY | J9: kg上限 | K9: g上限 | L9: DE | M9: AT | N9: BE | O9: BG | P9: CY | Q9: CZ | R9: DK | S9: EE | T9: ES | U9: FI | V9: FR | W9: GR | X9: HR | Y9: HU | Z9: IE | AA9: IT | AB9: LT | AC9: LU | AD9: LV | AE9: MT | AF9: NL | AG9: PL | AH9: PT | AI9: RO | AJ9: SE | AK9: SI | AL9: SK
B10: 0.1 | C10: =B10*1000 -> 100 | D10: 1157 | J10: 0.1 | K10: 100 | L10: 1440 | M10: 1942 | N10: 2234 | O10: 1883 | P10: 3861 | Q10: 2234 | R10: 2205 | S10: 2352 | T10: 1793 | U10: 2991 | V10: 1963 | W10: 1810 | X10: 2264 | Y10: 1810 | Z10: 2071 | AA10: 1996 | AB10: 1712 | AC10: 1979 | AD10: 2032 | AE10: 3015 | AF10: 2104 | AG10: 1610 | AH10: 1784 | AI10: 1738 | AJ10: 1629 | AK10: 2217 | AL10: 2160
B11: 0.2 | C11: =B11*1000 -> 200 | D11: 1289 | F11: 燃油率 | G11: 0.145 | J11: 0.2 | K11: 200 | L11: 1664 | M11: 2281 | N11: 2522 | O11: 2233 | P11: 4296 | Q11: 2515 | R11: 2471 | S11: 2751 | T11: 2119 | U11: 3255 | V11: 2313 | W11: 2239 | X11: 2613 | Y11: 2158 | Z11: 2411 | AA11: 2319 | AB11: 2119 | AC11: 2254 | AD11: 2437 | AE11: 3579 | AF11: 2367 | AG11: 1957 | AH11: 2090 | AI11: 2084 | AJ11: 1889 | AK11: 2569 | AL11: 2513
B12: 0.3 | C12: =B12*1000 -> 300 | D12: 1491 | J12: 0.3 | K12: 300 | L12: 1902 | M12: 2412 | N12: 2654 | O12: 2363 | P12: 4427 | Q12: 2646 | R12: 2603 | S12: 2882 | T12: 2248 | U12: 3386 | V12: 2445 | W12: 2370 | X12: 2741 | Y12: 2289 | Z12: 2541 | AA12: 2449 | AB12: 2248 | AC12: 2384 | AD12: 2567 | AE12: 3710 | AF12: 2498 | AG12: 2088 | AH12: 2221 | AI12: 2214 | AJ12: 2020 | AK12: 2699 | AL12: 2643
B13: 0.4 | C13: =B13*1000 -> 400 | D13: 1677 | F13: US寸法割増（円） | G13: 2475 | J13: 0.4 | K13: 400 | L13: 2044 | M13: 2829 | N13: 2971 | O13: 2799 | P13: 5027 | Q13: 2930 | R13: 2865 | S13: 3430 | T13: 2637 | U13: 3648 | V13: 2934 | W13: 2971 | X13: 3180 | Y13: 2728 | Z13: 2963 | AA13: 2838 | AB13: 2792 | AC13: 2691 | AD13: 3113 | AE13: 4569 | AF13: 2761 | AG13: 2520 | AH13: 2571 | AI13: 2654 | AJ13: 2281 | AK13: 3137 | AL13: 3092
B14: 0.5 | C14: =B14*1000 -> 500 | D14: 1943 | F14: EUバルキー（円） | G14: 2520 | J14: 0.5 | K14: 500 | L14: 2296 | M14: 3088 | N14: 3233 | O14: 3061 | P14: 5288 | Q14: 3190 | R14: 3126 | S14: 3691 | T14: 2897 | U14: 3909 | V14: 3196 | W14: 3233 | X14: 3442 | Y14: 2988 | Z14: 3224 | AA14: 3098 | AB14: 3053 | AC14: 2952 | AD14: 3374 | AE14: 4829 | AF14: 3021 | AG14: 2781 | AH14: 2832 | AI14: 2916 | AJ14: 2542 | AK14: 3396 | AL14: 3353
B15: 0.6 | C15: =B15*1000 -> 600 | D15: 2096 | F15: EU混雑時料金（円） | G15: 34 | J15: 0.6 | K15: 600 | L15: 2504 | M15: 3219 | N15: 3363 | O15: 3191 | P15: 5419 | Q15: 3321 | R15: 3256 | S15: 3821 | T15: 3028 | U15: 4040 | V15: 3326 | W15: 3363 | X15: 3572 | Y15: 3120 | Z15: 3353 | AA15: 3229 | AB15: 3182 | AC15: 3080 | AD15: 3504 | AE15: 4961 | AF15: 3152 | AG15: 2911 | AH15: 2962 | AI15: 3046 | AJ15: 2671 | AK15: 3527 | AL15: 3484
B16: 0.7 | C16: =B16*1000 -> 700 | D16: 2189 | F16: EU混雑時適用 | G16: 0 | J16: 0.7 | K16: 700 | L16: 2742 | M16: 3635 | N16: 3679 | O16: 3629 | P16: 6021 | Q16: 3601 | R16: 3521 | S16: 4368 | T16: 3413 | U16: 4304 | V16: 3823 | W16: 3963 | X16: 4012 | Y16: 3557 | Z16: 3775 | AA16: 3617 | AB16: 3729 | AC16: 3386 | AD16: 4046 | AE16: 5826 | AF16: 3416 | AG16: 3341 | AH16: 3408 | AI16: 3485 | AJ16: 3030 | AK16: 3965 | AL16: 3933
B17: 0.8 | C17: =B17*1000 -> 800 | D17: 2549 | F17: 追加送料（円） | G17: 0 | J17: 0.8 | K17: 800 | L17: 3102 | M17: 3766 | N17: 3807 | O17: 3759 | P17: 6151 | Q17: 3732 | R17: 3651 | S17: 4498 | T17: 3544 | U17: 4434 | V17: 3954 | W17: 4094 | X17: 4142 | Y17: 3688 | Z17: 3905 | AA17: 3747 | AB17: 3858 | AC17: 3516 | AD17: 4177 | AE17: 5955 | AF17: 3546 | AG17: 3472 | AH17: 3538 | AI17: 3615 | AJ17: 3161 | AK17: 4096 | AL17: 4063
B18: 0.9 | C18: =B18*1000 -> 900 | D18: 2660 | J18: 0.9 | K18: 900 | L18: 3319 | M18: 4027 | N18: 4069 | O18: 4021 | P18: 6413 | Q18: 3993 | R18: 3912 | S18: 4759 | T18: 3804 | U18: 4696 | V18: 4215 | W18: 4354 | X18: 4403 | Y18: 3947 | Z18: 4167 | AA18: 4009 | AB18: 4120 | AC18: 3776 | AD18: 4438 | AE18: 6217 | AF18: 3807 | AG18: 3733 | AH18: 3800 | AI18: 3877 | AJ18: 3420 | AK18: 4356 | AL18: 4323
B19: 1 | C19: =B19*1000 -> 1000 | D19: 2848 | J19: 1 | K19: 1000 | L19: 3400 | M19: 4441 | N19: 4390 | O19: 4461 | P19: 7012 | Q19: 4279 | R19: 4177 | S19: 5303 | T19: 4196 | U19: 4958 | V19: 4563 | W19: 4955 | X19: 4842 | Y19: 4386 | Z19: 4587 | AA19: 4396 | AB19: 4664 | AC19: 4063 | AD19: 4984 | AE19: 7079 | AF19: 4077 | AG19: 4168 | AH19: 4154 | AI19: 4315 | AJ19: 3681 | AK19: 4796 | AL19: 4770
B20: 1.1 | C20: =B20*1000 -> 1100 | D20: 2958 | J20: 1.1 | K20: 1100 | L20: 3635 | M20: 4571 | N20: 4521 | O20: 4589 | P20: 7142 | Q20: 4410 | R20: 4307 | S20: 5433 | T20: 4326 | U20: 5088 | V20: 4694 | W20: 5086 | X20: 4972 | Y20: 4516 | Z20: 4718 | AA20: 4527 | AB20: 4795 | AC20: 4194 | AD20: 5114 | AE20: 7209 | AF20: 4207 | AG20: 4298 | AH20: 4284 | AI20: 4446 | AJ20: 3812 | AK20: 4927 | AL20: 4900
B21: 1.2 | C21: =B21*1000 -> 1200 | D21: 3065 | J21: 1.2 | K21: 1200 | L21: 4043 | M21: 4829 | N21: 4780 | O21: 4851 | P21: 7404 | Q21: 4671 | R21: 4569 | S21: 5695 | T21: 4587 | U21: 5349 | V21: 4955 | W21: 5347 | X21: 5233 | Y21: 4778 | Z21: 4979 | AA21: 4788 | AB21: 5054 | AC21: 4455 | AD21: 5376 | AE21: 7470 | AF21: 4468 | AG21: 4558 | AH21: 4543 | AI21: 4707 | AJ21: 4072 | AK21: 5188 | AL21: 5162
B22: 1.3 | C22: =B22*1000 -> 1300 | D22: 3174 | J22: 1.3 | K22: 1300 | L22: 4114 | M22: 4961 | N22: 4911 | O22: 4981 | P22: 7533 | Q22: 4801 | R22: 4699 | S22: 5825 | T22: 4718 | U22: 5480 | V22: 5086 | W22: 5478 | X22: 5364 | Y22: 4908 | Z22: 5109 | AA22: 4919 | AB22: 5185 | AC22: 4585 | AD22: 5504 | AE22: 7601 | AF22: 4599 | AG22: 4688 | AH22: 4673 | AI22: 4838 | AJ22: 4203 | AK22: 5318 | AL22: 5292
B23: 1.4 | C23: =B23*1000 -> 1400 | D23: 3493 | J23: 1.4 | K23: 1400 | L23: 4177 | M23: 4961 | N23: 4911 | O23: 4981 | P23: 7533 | Q23: 4801 | R23: 4699 | S23: 5825 | T23: 4718 | U23: 5480 | V23: 5086 | W23: 5478 | X23: 5364 | Y23: 4908 | Z23: 5109 | AA23: 4919 | AB23: 5185 | AC23: 4585 | AD23: 5504 | AE23: 7601 | AF23: 4599 | AG23: 4688 | AH23: 4673 | AI23: 4838 | AJ23: 4203 | AK23: 5318 | AL23: 5292
B24: 1.5 | C24: =B24*1000 -> 1500 | D24: 3599 | J24: 1.5 | K24: 1500 | L24: 4741 | M24: 4961 | N24: 4911 | O24: 4981 | P24: 7533 | Q24: 4801 | R24: 4699 | S24: 5825 | T24: 4718 | U24: 5480 | V24: 5086 | W24: 5478 | X24: 5364 | Y24: 4908 | Z24: 5109 | AA24: 4919 | AB24: 5185 | AC24: 4585 | AD24: 5504 | AE24: 7601 | AF24: 4599 | AG24: 4688 | AH24: 4673 | AI24: 4838 | AJ24: 4203 | AK24: 5318 | AL24: 5292
B25: 1.6 | C25: =B25*1000 -> 1600 | D25: 3711 | F25: 出典：eBay SpeedPAK Economy、2026-07-30版、6・7・13・14・16頁。 | J25: 1.6 | K25: 1600 | L25: 5445 | M25: 6576 | N25: 6483 | O25: 6860 | P25: 12846 | Q25: 6095 | R25: 5944 | S25: 7550 | T25: 6235 | U25: 7030 | V25: 6687 | W25: 8101 | X25: 7302 | Y25: 6325 | Z25: 6746 | AA25: 6463 | AB25: 6649 | AC25: 5888 | AD25: 7342 | AE25: 10521 | AF25: 5825 | AG25: 6319 | AH25: 6429 | AI25: 6644 | AJ25: 5526 | AK25: 7013 | AL25: 6924
B26: 1.7 | C26: =B26*1000 -> 1700 | D26: 3816 | F26: 燃油：Orange Connex公式、2026-10-01発効14.5%。 | J26: 1.7 | K26: 1700 | L26: 5518 | M26: 6576 | N26: 6483 | O26: 6860 | P26: 12846 | Q26: 6095 | R26: 5944 | S26: 7550 | T26: 6235 | U26: 7030 | V26: 6687 | W26: 8101 | X26: 7302 | Y26: 6325 | Z26: 6746 | AA26: 6463 | AB26: 6649 | AC26: 5888 | AD26: 7342 | AE26: 10521 | AF26: 5825 | AG26: 6319 | AH26: 6429 | AI26: 6644 | AJ26: 5526 | AK26: 7013 | AL26: 6924
B27: 1.8 | C27: =B27*1000 -> 1800 | D27: 3928 | F27: EU基本料金表の掲載上限は20kg。超過は見積確認。 | J27: 1.8 | K27: 1800 | L27: 6092 | M27: 6576 | N27: 6483 | O27: 6860 | P27: 12846 | Q27: 6095 | R27: 5944 | S27: 7550 | T27: 6235 | U27: 7030 | V27: 6687 | W27: 8101 | X27: 7302 | Y27: 6325 | Z27: 6746 | AA27: 6463 | AB27: 6649 | AC27: 5888 | AD27: 7342 | AE27: 10521 | AF27: 5825 | AG27: 6319 | AH27: 6429 | AI27: 6644 | AJ27: 5526 | AK27: 7013 | AL27: 6924
B28: 1.9 | C28: =B28*1000 -> 1900 | D28: 4768 | F28: 資料末尾に÷6,000の注記もあるため、基本料金ページの÷8,000を採用。 | J28: 1.9 | K28: 1900 | L28: 6161 | M28: 7304 | N28: 7213 | O28: 7588 | P28: 13576 | Q28: 6822 | R28: 6672 | S28: 8279 | T28: 6963 | U28: 7759 | V28: 7414 | W28: 8830 | X28: 8031 | Y28: 7054 | Z28: 7474 | AA28: 7193 | AB28: 7378 | AC28: 6616 | AD28: 8072 | AE28: 11250 | AF28: 6554 | AG28: 7048 | AH28: 7159 | AI28: 7373 | AJ28: 6254 | AK28: 7742 | AL28: 7654
B29: 2 | C29: =B29*1000 -> 2000 | D29: 4947 | F29: https://www.orangeconnex.jp/newsDetail?title=Fuel+Surcharge+Update+for+Economy+Service+%E2%80%94+Effective+October+1,+2026 | J29: 2 | K29: 2000 | L29: 7032 | M29: 7304 | N29: 7213 | O29: 7588 | P29: 13576 | Q29: 6822 | R29: 6672 | S29: 8279 | T29: 6963 | U29: 7759 | V29: 7414 | W29: 8830 | X29: 8031 | Y29: 7054 | Z29: 7474 | AA29: 7193 | AB29: 7378 | AC29: 6616 | AD29: 8072 | AE29: 11250 | AF29: 6554 | AG29: 7048 | AH29: 7159 | AI29: 7373 | AJ29: 6254 | AK29: 7742 | AL29: 7654
B30: 2.5 | C30: =B30*1000 -> 2500 | D30: 5264 | J30: 2.5 | K30: 2500 | L30: 8279 | M30: 9106 | N30: 8796 | O30: 9442 | P30: 16862 | Q30: 8336 | R30: 8350 | S30: 9790 | T30: 8705 | U30: 9225 | V30: 9152 | W30: 11230 | X30: 10087 | Y30: 8567 | Z30: 9294 | AA30: 9149 | AB30: 8890 | AC30: 8177 | AD30: 9583 | AE30: 14054 | AF30: 8022 | AG30: 8893 | AH30: 8788 | AI30: 9225 | AJ30: 7714 | AK30: 9248 | AL30: 9061
B31: 3 | C31: =B31*1000 -> 3000 | D31: 5973 | J31: 3 | K31: 3000 | L31: 9407 | M31: 10182 | N31: 9654 | O31: 10569 | P31: 19424 | Q31: 9113 | R31: 9084 | S31: 10569 | T31: 9719 | U31: 9963 | V31: 10160 | W31: 12896 | X31: 11317 | Y31: 9344 | Z31: 10377 | AA31: 10163 | AB31: 9668 | AC31: 9003 | AD31: 10361 | AE31: 16129 | AF31: 8759 | AG31: 10005 | AH31: 9564 | AI31: 10353 | AJ31: 8441 | AK31: 10029 | AL31: 9838
B32: 3.5 | C32: =B32*1000 -> 3500 | D32: 6562 | J32: 3.5 | K32: 3500 | L32: 11430 | M32: 11984 | N32: 11800 | O32: 13286 | P32: 22713 | Q32: 10622 | R32: 10895 | S32: 12078 | T32: 12185 | U32: 11776 | V32: 11825 | W32: 15293 | X32: 13520 | Y32: 10852 | Z32: 12194 | AA32: 12029 | AB32: 11176 | AC32: 10597 | AD32: 11871 | AE32: 18931 | AF32: 10224 | AG32: 12146 | AH32: 11077 | AI32: 12337 | AJ32: 10183 | AK32: 11538 | AL32: 11346
B33: 4 | C33: =B33*1000 -> 4000 | D33: 7266 | J33: 4 | K33: 4000 | L33: 12560 | M33: 12713 | N33: 12529 | O33: 14015 | P33: 23443 | Q33: 11352 | R33: 11625 | S33: 12808 | T33: 12915 | U33: 12504 | V33: 12554 | W33: 16022 | X33: 14248 | Y33: 11582 | Z33: 12922 | AA33: 12758 | AB33: 11905 | AC33: 11326 | AD33: 12599 | AE33: 19662 | AF33: 10954 | AG33: 12876 | AH33: 11806 | AI33: 13066 | AJ33: 10913 | AK33: 12267 | AL33: 12077
B34: 4.5 | C34: =B34*1000 -> 4500 | D34: 8615 | J34: 4.5 | K34: 4500 | L34: 13709 | M34: 14516 | N34: 14113 | O34: 16011 | P34: 26735 | Q34: 12859 | R34: 13088 | S34: 14313 | T34: 14421 | U34: 13969 | V34: 14063 | W34: 18420 | X34: 16201 | Y34: 13088 | Z34: 14740 | AA34: 14500 | AB34: 13413 | AC34: 12884 | AD34: 14105 | AE34: 22463 | AF34: 12417 | AG34: 14717 | AH34: 13313 | AI34: 14918 | AJ34: 12371 | AK34: 13775 | AL34: 13585
B35: 5 | C35: =B35*1000 -> 5000 | D35: 11065 | J35: 5 | K35: 5000 | L35: 14829 | M35: 16321 | N35: 15694 | O35: 18032 | P35: 30020 | Q35: 14360 | R35: 14554 | S35: 15822 | T35: 15931 | U35: 15774 | V35: 15570 | W35: 20817 | X35: 17693 | Y35: 14596 | Z35: 16553 | AA35: 16240 | AB35: 14921 | AC35: 14440 | AD35: 15615 | AE35: 25267 | AF35: 13885 | AG35: 16562 | AH35: 14821 | AI35: 16966 | AJ35: 13829 | AK35: 15282 | AL35: 15096
B36: 5.5 | C36: =B36*1000 -> 5500 | D36: 11789 | J36: 5.5 | K36: 5500 | L36: 16905 | M36: 17396 | N36: 16554 | O36: 18990 | P36: 32586 | Q36: 15141 | R36: 15290 | S36: 16601 | T36: 16708 | U36: 16554 | V36: 16353 | W36: 22486 | X36: 18493 | Y36: 15375 | Z36: 17640 | AA36: 17120 | AB36: 15698 | AC36: 15271 | AD36: 16393 | AE36: 27340 | AF36: 14621 | AG36: 17677 | AH36: 15599 | AI36: 18165 | AJ36: 14559 | AK36: 16059 | AL36: 15872
B37: 6 | C37: =B37*1000 -> 6000 | D37: 12576 | J37: 6 | K37: 6000 | L37: 18028 | M37: 19201 | N37: 18138 | O37: 20501 | P37: 35874 | Q37: 16651 | R37: 16755 | S37: 18112 | T37: 18214 | U37: 18064 | V37: 17858 | W37: 24883 | X37: 20006 | Y37: 16886 | Z37: 19459 | AA37: 18626 | AB37: 17211 | AC37: 16828 | AD37: 17904 | AE37: 30143 | AF37: 16088 | AG37: 19517 | AH37: 17109 | AI37: 20103 | AJ37: 16017 | AK37: 17567 | AL37: 17380
B38: 6.5 | C38: =B38*1000 -> 6500 | D38: 13354 | J38: 6.5 | K38: 6500 | L38: 19169 | M38: 19930 | N38: 18866 | O38: 21229 | P38: 36604 | Q38: 17379 | R38: 17485 | S38: 18841 | T38: 18944 | U38: 18792 | V38: 18588 | W38: 25613 | X38: 20733 | Y38: 17615 | Z38: 20189 | AA38: 19356 | AB38: 17939 | AC38: 17555 | AD38: 18634 | AE38: 30872 | AF38: 16816 | AG38: 20246 | AH38: 17838 | AI38: 20831 | AJ38: 16746 | AK38: 18295 | AL38: 18111
B39: 7 | C39: =B39*1000 -> 7000 | D39: 14344 | J39: 7 | K39: 7000 | L39: 21220 | M39: 23094 | N39: 21528 | O39: 22960 | P39: 47195 | Q39: 19087 | R39: 19199 | S39: 20544 | T39: 20651 | U39: 22170 | V39: 20300 | W39: 31768 | X39: 22438 | Y39: 19318 | Z39: 22664 | AA39: 21052 | AB39: 19642 | AC39: 19526 | AD39: 20337 | AE39: 39063 | AF39: 19009 | AG39: 23629 | AH39: 19544 | AI39: 24657 | AJ39: 18348 | AK39: 20006 | AL39: 19818
B40: 7.5 | C40: =B40*1000 -> 7500 | D40: 15144 | J40: 7.5 | K40: 7500 | L40: 22364 | M40: 24552 | N40: 22986 | O40: 24418 | P40: 48654 | Q40: 20546 | R40: 20658 | S40: 22001 | T40: 22111 | U40: 23629 | V40: 21757 | W40: 33227 | X40: 23896 | Y40: 20777 | Z40: 24123 | AA40: 22512 | AB40: 21102 | AC40: 20984 | AD40: 21794 | AE40: 40521 | AF40: 20467 | AG40: 25086 | AH40: 21001 | AI40: 26115 | AJ40: 19806 | AK40: 21463 | AL40: 21277
...

Sheet FedEx 送料
I1: …入力箇所(半角数値)
A2: 純送料 | B2: FICP | D2: 燃油率（手動） | E2: US割増 円/kg | F2: CPaSS割引 | G2: EU割増 円/kg | H2: EU H/M割引 | I2: 割増最低 円 | J2: EU基本送料 | K2: EU割増金 | L2: EU燃油 | M2: EU送料計 | O2: US郵便番号（任意）
B3: {=IF('計算詳細'!D4<=0,"重量未入力",IF(MIN('計算詳細'!C8:E8)<=0,"サイズ未入力",IF(OR(MAX(ROUNDUP('計算詳細'!C8,0),ROUNDUP('計算詳細'!D8,0),ROUNDUP('計算詳細'!E8,0))>274,2*SUM(ROUNDUP('計算詳細'!C8,0),ROUNDUP('計算詳細'!D8,0),ROUNDUP('計算詳細'!E8,0))-MAX(ROUNDUP('計算詳細'!C8,0),ROUNDUP('計算詳細'!D8,0),ROUNDUP('計算詳細'!E8,0))>330,'計算詳細'!Q9>68000),"発送不可",INDEX($D$21:$H$108,MATCH('計算詳細'!Q9,$C$21:$C$108,0),MATCH($P$3,$D$18:$H$18,0)))))} -> 3061 | D3: 0.5125 | E3: 242 | F3: 0 | G3: 200 | H3: 0.5 | I3: 37 | J3: {=IF('計算詳細'!D4<=0,"重量未入力",IF(MIN('計算詳細'!C8:E8)<=0,"サイズ未入力",IF(OR(MAX(ROUNDUP('計算詳細'!C8,0),ROUNDUP('計算詳細'!D8,0),ROUNDUP('計算詳細'!E8,0))>274,2*SUM(ROUNDUP('計算詳細'!C8,0),ROUNDUP('計算詳細'!D8,0),ROUNDUP('計算詳細'!E8,0))-MAX(ROUNDUP('計算詳細'!C8,0),ROUNDUP('計算詳細'!D8,0),ROUNDUP('計算詳細'!E8,0))>330,'計算詳細'!Q9>68000),"発送不可",INDEX($D$21:$H$108,MATCH('計算詳細'!Q9,$C$21:$C$108,0),MATCH($K$6,$D$18:$H$18,0)))))} -> 3161 | K3: =IF(ISNUMBER(J3),MAX($I$3,'計算詳細'!Q9/1000*$G$3)*(1-IF(AND(OR($K$6="H",$K$6="M"),$P$4>=DATE(2026,9,21),$P$4<=DATE(2026,11,1)),$H$3,0)),J3) -> 200 | L3: =IF(ISNUMBER(P10),ROUND(P10*$D$3,0),P10) -> 1723 | M3: =IF(ISNUMBER(J3),SUM(J3,K3,L3,K9,K10,P7,P8)-ROUND((J3+L3)*$F$3,0),J3) -> 5084 | O3: US適用ゾーン | P3: =IF(ISNUMBER(P2),IF(OR(AND(P2>=83200,P2<=83999),AND(P2>=84000,P2<=84799),AND(P2>=85000,P2<=86599),AND(P2>=89000,P2<=89899),AND(P2>=90000,P2<=96699),AND(P2>=97000,P2<=97999),AND(P2>=98000,P2<=99499)),"E","F"),LEFT(K5,1)) -> E
E4: =IF(ISNUMBER(B3),MAX($I$3,'計算詳細'!Q9/1000*$E$3),B3) -> 484 | O4: 適用日 | P4: =TODAY() -> 46308
A5: サーチャージ | B5: FICP | J5: US料金ゾーン | K5: E（西部） | O5: 課金重量（g） | P5: ='計算詳細'!Q9 -> 2000
B6: =IF(ISNUMBER(P9),ROUND(P9*$D$3,0),P9) -> 1817 | J6: EU料金ゾーン | K6: ='計算詳細'!Q2 -> M | O6: US地域外配達料 | P6: =IF(K11="通常",0,IF(K11="A",0,IF(K11="B",IF(OR(P3="H",P3="I",P3="M"),0,MAX(2990,'計算詳細'!Q9/1000*58)),IF(OR(P3="H",P3="M"),0,MAX(3890,'計算詳細'!Q9/1000*80))))) -> 0
J7: EU配送先 | K7: ='設定'!B27 -> イタリア | O7: EU地域外配達料 | P7: =IF(K12="通常",0,IF(K12="A",0,IF(K12="B",IF(OR(K6="H",K6="I",K6="M"),0,MAX(2990,'計算詳細'!Q9/1000*58)),IF(OR(K6="H",K6="M"),0,MAX(3890,'計算詳細'!Q9/1000*80))))) -> 0
A8: Cpass割引 | B8: FICP | J8: 梱包 | K8: 独自梱包 | O8: 非標準貨物割増 | P8: =IF(K10>0,770*(1-IF(AND(P4>=DATE(2026,9,21),P4<=DATE(2027,3,31)),1,0)),0) -> 0
B9: =IF(ISNUMBER(B3),-ROUND((B3+B6)*$F$3,0),B3) -> 0 | J9: 追加送料（円） | K9: 0 | O9: US燃油対象額 | P9: =IF(ISNUMBER(B3),SUM(B3,E4,K9,K10,P6,P8),B3) -> 3545
J10: 特別取扱料（円） | K10: =IF(OR(MAX(ROUNDUP('計算詳細'!C8,0),ROUNDUP('計算詳細'!D8,0),ROUNDUP('計算詳細'!E8,0))>243,2*SUM(ROUNDUP('計算詳細'!C8,0),ROUNDUP('計算詳細'!D8,0),ROUNDUP('計算詳細'!E8,0))-MAX(ROUNDUP('計算詳細'!C8,0),ROUNDUP('計算詳細'!D8,0),ROUNDUP('計算詳細'!E8,0))>330,'計算詳細'!D4>50000,ROUNDUP('計算詳細'!C8,0)*ROUNDUP('計算詳細'!D8,0)*ROUNDUP('計算詳細'!E8,0)>283168),8800,IF(OR(OR(MAX(ROUNDUP('計算詳細'!C8,0),ROUNDUP('計算詳細'!D8,0),ROUNDUP('計算詳細'!E8,0))>121,SUM(ROUNDUP('計算詳細'!C8,0),ROUNDUP('計算詳細'!D8,0),ROUNDUP('計算詳細'!E8,0))-MAX(ROUNDUP('計算詳細'!C8,0),ROUNDUP('計算詳細'!D8,0),ROUNDUP('計算詳細'!E8,0))-MIN(ROUNDUP('計算詳細'!C8,0),ROUNDUP('計算詳細'!D8,0),ROUNDUP('計算詳細'!E8,0))>76,2*SUM(ROUNDUP('計算詳細'!C8,0),ROUNDUP('計算詳細'!D8,0),ROUNDUP('計算詳細'!E8,0))-MAX(ROUNDUP('計算詳細'!C8,0),ROUNDUP('計算詳細'!D8,0),ROUNDUP('計算詳細'!E8,0))>266,ROUNDUP('計算詳細'!C8,0)*ROUNDUP('計算詳細'!D8,0)*ROUNDUP('計算詳細'!E8,0)>169901),'計算詳細'!D4>25000,P11=1),3390,0)) -> 0 | O10: EU燃油対象額 | P10: =IF(ISNUMBER(J3),SUM(J3,K3,K9,K10,P7,P8),J3) -> 3361
A11: 送料計 | B11: FICP | J11: US地域外配達 | K11: 通常 | O11: 特別取扱（梱包） | P11: 0
B12: =IF(ISNUMBER(B3),SUM(B3,B6,B9,E4,K9,K10,P6,P8),B3) -> 5362 | J12: EU地域外配達 | K12: 通常 | O12: 梱包最低重量（g） | P12: =IF(K8="FedEx Box",1000,IF(K8="FedEx Tube",4000,0)) -> 0
J13: 割増：FedEx公式2026-09-21版。FICPはPriority：US242円/kg、EU200円/kg。
B14: 注意: | J14: H/M割引50%：9/21～11/1。非標準貨物割増770円は3/31まで100%割引。 | O14: 郵便番号が空欄ならK5のゾーンを使用。
B15: FedEx FICP 2026-10-01版：12～15・38～41頁。USゾーンE/F、EUゾーンH/I/M。 | O15: 地域外区分は配送先の該当区分を選択。
B16: 燃油D3：2026-10-05～11の公表値51.25%。手動変更可。割増・対象追加送料にも適用。 | O16: FICPのPak／Envelopeは荷物用重量料金。
J17: https://www.fedex.com/ja-jp/shipping/surcharges/demand-surcharge.html | O17: 出典：SpeedPAK FedExガイド4・12～15・38～41頁。
B18: 基本料金単位：円 | D18: E | E18: F | F18: H | G18: I | H18: M | J18: 寸法・重量条件：fedex-rates-ficp-sur-ja-jp-2026.pdf。2026年の容積基準も適用。 | O18: 燃油：FedEx日本公式の週別燃油データ（2026-10-05～11）。
B19: 量 kg | C19: 量 g | D19: E（US西部） | E19: F（US東部） | F19: H（EU） | G19: I（EU） | H19: M（EU） | O19: https://www.fedex.com/ja-jp/shipping/surcharges.html
B20: インターナショナルコネクトプラスサービス(FICP)(68 kg以下) | F20: 各辺の小数は整数cmへ切り上げ。実重量・容積重量の大きい方を料金段階へ切り上げ。
B21: 0.5 | C21: =B21*1000 -> 500 | D21: 2082 | E21: 2115 | F21: 2721 | G21: 2894 | H21: 2071
B22: 1 | C22: =B22*1000 -> 1000 | D22: 2558 | E22: 2599 | F22: 3356 | G22: 3569 | H22: 2417
B23: 1.5 | C23: =B23*1000 -> 1500 | D23: 2797 | E23: 2840 | F23: 3993 | G23: 4170 | H23: 2814
B24: 2 | C24: =B24*1000 -> 2000 | D24: 3061 | E24: 3108 | F24: 4487 | G24: 4799 | H24: 3161
B25: 2.5 | C25: =B25*1000 -> 2500 | D25: 3328 | E25: 3383 | F25: 4981 | G25: 5429 | H25: 3512
B26: 3 | C26: =B26*1000 -> 3000 | D26: 3492 | E26: 3540 | F26: 5249 | G26: 5825 | H26: 3535
B27: 3.5 | C27: =B27*1000 -> 3500 | D27: 3549 | E27: 3593 | F27: 5370 | G27: 6001 | H27: 3594
B28: 4 | C28: =B28*1000 -> 4000 | D28: 3973 | E28: 4022 | F28: 5837 | G28: 6590 | H28: 3904
B29: 4.5 | C29: =B29*1000 -> 4500 | D29: 4395 | E29: 4451 | F29: 6304 | G29: 7177 | H29: 4218
B30: 5 | C30: =B30*1000 -> 5000 | D30: 4718 | E30: 4718 | F30: 6770 | G30: 7761 | H30: 4530
B31: 5.5 | C31: =B31*1000 -> 5500 | D31: 5043 | E31: 5043 | F31: 8181 | G31: 9824 | H31: 5273
B32: 6 | C32: =B32*1000 -> 6000 | D32: 5366 | E32: 5366 | F32: 8518 | G32: 10109 | H32: 5491
... B108: 68 | C108: =B108*1000 -> 68000 | D108: 58791 | E108: 64872 | F108: 83964 | G108: 91890 | H108: 66041

Sheet DHL　送料
J1: …入力箇所(半角数値)
A2: 純送料 | B2: DHL | D2: 燃油率（参考値） | E2: 燃油割引 | F2: US割増 円/kg | G2: CPaSS割引 | H2: EU割増 円/kg | I2: US規制料適用 | J2: US元払い適用
B3: {=IF('計算詳細'!D4<=0,"重量未入力",IF(MIN('計算詳細'!C8:E8)<=0,"サイズ未入力",IF(OR('計算詳細'!D4>70000,MAX('計算詳細'!C8:E8)>120,SUM('計算詳細'!C8:E8)-MAX('計算詳細'!C8:E8)-MIN('計算詳細'!C8:E8)>80,'計算詳細'!H9>153600),"発送不可",INDEX($D$21:$D$194,MATCH('計算詳細'!Q10,$C$21:$C$194,0)))))} -> 3365 | D3: 0.3975 | E3: 0.25 | F3: 243 | G3: 0 | H3: 207 | I3: 1 | J3: 1
F4: =IF(ISNUMBER(B3),'計算詳細'!Q10/1000*$F$3,B3) -> 486
A5: サーチャージ | B5: DHL | F5: 課金重量（kg） | G5: ='計算詳細'!Q10/1000 -> 2 | J5: EU基本送料 | K5: EU割増金 | L5: EU燃油 | M5: EU送料計
A6: (割引込み) | B6: =IF(ISNUMBER(B3),ROUND((B3+F4+K9+K10)*$D$3*(1-$E$3),0),B3) -> 1148 | J6: {=IF('計算詳細'!D4<=0,"重量未入力",IF(MIN('計算詳細'!C8:E8)<=0,"サイズ未入力",IF(OR('計算詳細'!D4>70000,MAX('計算詳細'!C8:E8)>120,SUM('計算詳細'!C8:E8)-MAX('計算詳細'!C8:E8)-MIN('計算詳細'!C8:E8)>80,'計算詳細'!H9>153600),"発送不可",INDEX($E$21:$E$194,MATCH('計算詳細'!Q10,$C$21:$C$194,0)))))} -> 3848 | K6: =IF(ISNUMBER(J6),'計算詳細'!Q10/1000*$H$3,J6) -> 414 | L6: =IF(ISNUMBER(J6),ROUND((J6+K6+K9+K10)*$D$3*(1-$E$3),0),J6) -> 1271 | M6: =IF(ISNUMBER(J6),J6+K6+L6+K9+K10-ROUND((J6+L6)*$G$3,0),J6) -> 5533
J7: EU配送先 | K7: ='設定'!B27 -> イタリア
A8: Cpass割引 | B8: DHL
B9: =IF(ISNUMBER(B3),-ROUND((B3+B6)*$G$3,0),B3) -> 0 | J9: 追加送料（円） | K9: 0
J10: 特別取扱料（円） | K10: =IF('計算詳細'!H9>70000,17000,IF(OR(MAX('計算詳細'!C8:E8)>100,'計算詳細'!D4>25000),3300,0)) -> 0
A11: 送料計 | B11: DHL
B12: =IF(ISNUMBER(B3),SUM(B3,B6,B9,F4,K9,K10),B3) -> 4999
J13: 2026-10-01～2027-02-05：繁忙期 US243円/kg、EU207円/kg（10%割引後）。
B14: 注意: | J14: https://www.orangeconnex.jp/newsDetail?title=Demand+Surcharge+and+U.S.+Customs+Surcharge+Update+for+SpeedPAK+Ship+via+DHL+%E2%80%94+Effective+October+1,+2026
B15: DHL Express Worldwide 2026-10-01版：11～17・25～27頁。EU27か国はZone 6。
B16: 燃油率D3は元表の参考値39.75%。E3の25%割引を適用。追加送料はK9。
B17: 基本料金単位：円
B18: 量 g | C18: 量 g | D18: Zone 10（US） | E18: Zone 6（EU）
B19: な国･地域名
B20: 荷物（非書類）
B21: 0.5 | C21: =B21*1000 -> 500 | D21: 2727 | E21: 2265
B22: 1 | C22: =B22*1000 -> 1000 | D22: 3078 | E22: 3177
B23: 1.5 | C23: =B23*1000 -> 1500 | D23: 3207 | E23: 3482
B24: 2 | C24: =B24*1000 -> 2000 | D24: 3365 | E24: 3848
B25: 2.5 | C25: =B25*1000 -> 2500 | D25: 3753 | E25: 4275
B26: 3 | C26: =B26*1000 -> 3000 | D26: 4138 | E26: 4763
B27: 3.5 | C27: =B27*1000 -> 3500 | D27: 4616 | E27: 5294
B28: 4 | C28: =B28*1000 -> 4000 | D28: 5010 | E28: 5702
B29: 4.5 | C29: =B29*1000 -> 4500 | D29: 5405 | E29: 5830
B30: 5 | C30: =B30*1000 -> 5000 | D30: 5800 | E30: 5956
B31: 5.5 | C31: =B31*1000 -> 5500 | D31: 6194 | E31: 6082
B32: 6 | C32: =B32*1000 -> 6000 | D32: 6587 | E32: 6210
... B77: 37 | C77: =B77*1000 -> 37000 | D77: 40156 | E77: 50326
B78: 38 | C78: 38000 | D78: 41239 | E78: 51418
B79: 39 | C79: 39000 | D79: 42323 | E79: 52511
B80: 40 | C80: 40000 | D80: 43406 | E80: 53604
B81: 41 | C81: 41000 | D81: 44490 | E81: 54696
B82: 42 | C82: 42000 | D82: 45574 | E82: 55789
B83: 43 | C83: 43000 | D83: 46657 | E83: 56881
B84: 44 | C84: 44000 | D84: 47742 | E84: 57974
...

Sheet 計算詳細
B1: レート | C1: 送料 | P1: EU国コード | Q1: {=INDEX('設定'!G50:G76,MATCH('設定'!B27,'設定'!F50:F76,0))} -> IT
B2: ='設定'!B4 -> 158.158 | C2: ='計算式'!T4 -> 0 | P2: FedEx EUゾーン | Q2: {=INDEX('設定'!H50:H76,MATCH('設定'!B27,'設定'!F50:F76,0))} -> M
B3: 販売価格(＄) | C3: 仕入価格 | D3: 重量 | E3: ebay手数料 | F3: カテゴリーNo | G3: 海外手数料 | H3: ペイオニア | I3: PL(広告) | J3: ＋3% | K3: 割引切手 | L3: 関税率 | P3: US通関方式 | Q3: =IF('設定'!B51="自動",IF(C4/B2>2500,"正式","簡易"),'設定'!B51) -> 簡易
B4: =IF(ISNUMBER('計算式'!B2),'計算式'!B2,"") -> 82.98 | C4: =IF(ISNUMBER('計算式'!L2),'計算式'!L2,"") -> 5800 | D4: ='計算式'!V2 -> 1500 | E4: {=IF(COUNTIF('カテゴリー手数料一覧'!$B$1:$U$1,1)=0,"カテゴリ未登録",INDEX('カテゴリー手数料一覧'!$B$2:$U$2,1,MATCH(1,'カテゴリー手数料一覧'!$B$1:$U$1,0)))} -> 0.127 | F4: =TRIM('計算式'!AF2) -> 69528 | G4: ='設定'!B5 -> 0.0135 | H4: ='設定'!B6 -> 0.025 | I4: ='設定'!B7 -> 0 | J4: ='設定'!B8 -> On | K4: ='設定'!B9 -> 0.1 | L4: ='設定'!B10 -> 0.125 | P4: EU申告額 EUR | Q4: =C4/'設定'!B42 -> 32.793373
P5: EU関税・税金 | Q5: =IF(ISNUMBER('設定'!B50),'設定'!B50,IF(Q4>150,"EU関税額を入力",ROUND('設定'!B28*'設定'!B45,0))) -> 555
P6: US Economy関税 | Q6: =IF(ISNUMBER('設定'!B47),'設定'!B47,ROUND(C4*L4,0)) -> 725
B7: 適用重量 | C7: 長さ（最長辺） | D7: 幅 | E7: 高さ | F7: 体積重量A | G7: 体積重量B | H7: FedEx/DHL 適用重量（g） | I7: 関税コスト | J7: F/D | K7: DHL手数料 | L7: MPF | P7: US FedEx関税 | Q7: =IF(ISNUMBER('設定'!B57),'設定'!B57,ROUND(C4*L4,0)) -> 725
B8: =MAX(D4,F8) -> 1500 | C8: ='計算式'!B4 -> 20 | D8: ='計算式'!H4 -> 20 | E8: ='計算式'!N4 -> 20 | F8: =PRODUCT(C8:E8)/'設定'!B20*1000 -> 1000 | G8: =PRODUCT(C8:E8)/'設定'!B21*1000 -> 1600 | H8: =MAX(ROUNDUP(D4,0),ROUNDUP(ROUNDUP(C8,0)*ROUNDUP(D8,0)*ROUNDUP(E8,0)/'設定'!B21*1000,0),IF(OR(MAX(ROUNDUP(C8,0),ROUNDUP(D8,0),ROUNDUP(E8,0))>121,SUM(ROUNDUP(C8,0),ROUNDUP(D8,0),ROUNDUP(E8,0))-MAX(ROUNDUP(C8,0),ROUNDUP(D8,0),ROUNDUP(E8,0))-MIN(ROUNDUP(C8,0),ROUNDUP(D8,0),ROUNDUP(E8,0))>76,2*SUM(ROUNDUP(C8,0),ROUNDUP(D8,0),ROUNDUP(E8,0))-MAX(ROUNDUP(C8,0),ROUNDUP(D8,0),ROUNDUP(E8,0))>266,ROUNDUP(C8,0)*ROUNDUP(D8,0)*ROUNDUP(E8,0)>169901),18000,0),'FedEx 送料'!P12) -> 1600 | I8: =IF(ISNUMBER(I16),Q6+ROUND(Q6*'設定'!B16,0)+'設定'!B17,I16) -> 985 | J8: =Q19 -> 1187 | K8: =Q18 -> 1068 | L8: =Q12 -> 438 | P8: US DHL関税 | Q8: =IF(ISNUMBER('設定'!B58),'設定'!B58,ROUND(C4*L4,0)) -> 725
H9: =ROUNDUP(MAX(D4,G8),0) -> 1600 | P9: FedEx課金重量 g | Q9: =IF(H8<=20000,CEILING(H8,500),CEILING(H8,1000)) -> 2000
P10: DHL課金重量 g | Q10: =IF(H9<=20000,CEILING(H9,500),CEILING(H9,1000)) -> 2000
M11: 推定配送料 | P11: Economy課金重量 g | Q11: =ROUNDUP(B8,0) -> 1500
B12: JP post | C12: エアパケ(US) | D12: エアパケ(EU) | E12: ＥＭＳ | F12: 印刷物書留 | G12: 書状書留 | I12: エコノミー | J12: FedEx(FICP) | K12: DHL | M12: エコノミー | P12: FedEx US MPF 円 | Q12: =ROUND(IF(Q3="正式",MIN('設定'!B54,MAX('設定'!B53,C4/B2*'設定'!B52)),'設定'!B11)*B2,0) -> 438
B13: 利益 | C13: =IF(ISNUMBER(C16),IF(ISNUMBER(B20),B20-C4-C16,B20),C16) -> 1032.2185 | D13: =IF(ISNUMBER(D16),IF(ISNUMBER(B20),B20-C4-D16,B20),D16) -> 1698.2185 | E13: =IF(ISNUMBER(E16),IF(ISNUMBER(B21),B21-C4-E16,B21),E16) -> -1125.8407 | F13: =IF(ISNUMBER(F16),IF(ISNUMBER(B21),B21-C4-F16,B21),F16) -> 1016.1593 | G13: =IF(ISNUMBER(G16),IF(ISNUMBER(B21),B21-C4-G16,B21),G16) -> -99.840709 | I13: =IF(ISNUMBER(M13),IF(ISNUMBER(B20),B20-C4-M13,B20),M13) -> -347.78155 | J13: =IF(ISNUMBER(J16),IF(ISNUMBER(B20),B20-C4-J16-Q19,B20),J16) -> -1790.7815 | K13: =IF(ISNUMBER(K16),IF(ISNUMBER(B20),B20-C4-K16-Q20,B20),K16) -> -2071.7815 | M13: ='エコノミー送料'!G6 -> 5106 | P13: DHL US規制料 円 | Q13: =IF(AND(Q3="簡易",'DHL 送料'!I3=1),ROUND('設定'!B55*B2,0),0) -> 218
B14: 還付込み | C14: =IF(ISNUMBER(C13),C13+B22,C13) -> 1559.4912 | D14: =IF(ISNUMBER(D13),D13+B22,D13) -> 2225.4912 | E14: =IF(ISNUMBER(E13),E13+B22,E13) -> -598.56798 | F14: =IF(ISNUMBER(F13),F13+B22,F13) -> 1543.432 | G14: =IF(ISNUMBER(G13),G13+B22,G13) -> 427.43202 | I14: =IF(ISNUMBER(I13),I13+B22,I13) -> 179.49118 | J14: =IF(ISNUMBER(J13),J13+B22,J13) -> -1263.5088 | K14: =IF(ISNUMBER(K13),K13+B22,K13) -> -1544.5088 | P14: DHL US MPF 円 | Q14: =IF(Q3="正式",ROUND(MIN('設定'!B54,MAX('設定'!B53,C4/B2*'設定'!B52))*B2,0),0) -> 0
M15: US Zonos 利益 | N15: US Zonos 関税対象外 利益 | O15: EU Zonos 利益 | P15: DHL US税金元払い 円 | Q15: =IF(AND('DHL 送料'!J3=1,Q8>0),ROUND(MAX(Q8*'設定'!B59,'設定'!B60),0),0) -> 850
B16: 送料 | C16: {=IF(D4<=0,"重量未入力",IF(D4>MAX('送料'!$I$2:$I$21),"発送不可",INDEX('送料'!$J$2:$J$21,COUNTIF('送料'!$I$2:$I$21,"<"&D4)+1)*(1-K4)))} -> 3726 | D16: {=IF(D4<=0,"重量未入力",IF(D4>MAX('送料'!$B$2:$B$21),"発送不可",INDEX('送料'!$C$2:$C$21,COUNTIF('送料'!$B$2:$B$21,"<"&D4)+1)*(1-K4)))} -> 3060 | E16: {=IF(D4<=0,"重量未入力",IF(D4>MAX('送料'!$B$23:$B$64),"発送不可",INDEX('送料'!$C$23:$C$64,COUNTIF('送料'!$B$23:$B$64,"<"&D4)+1)*(1-K4)))} -> 5940 | F16: {=IF(D4<=0,"重量未入力",IF(D4>MAX('送料'!$B$66:$B$89),"発送不可",INDEX('送料'!$C$66:$C$89,COUNTIF('送料'!$B$66:$B$89,"<"&D4)+1)*(1-K4)))} -> 3798 | G16: {=IF(D4<=0,"重量未入力",IF(D4>MAX('送料'!$L$2:$L$7),"発送不可",INDEX('送料'!$M$2:$M$7,COUNTIF('送料'!$L$2:$L$7,"<"&D4)+1)*(1-K4)))} -> 4914 | I16: {=IF(D4<=0,"重量未入力",IF(MIN(C8:E8)<=0,"サイズ未入力",IF(OR(MAX(C8:E8)>66,2*SUM(C8:E8)-MAX(C8:E8)>274,C4/B2>1200),"発送不可",IF('エコノミー送料'!G2="本土48州以外",IF(Q11>15000,"発送不可",INDEX('エコノミー送料'!D82:D127,COUNTIF('エコノミー送料'!C82:C127,"<"&Q11)+1)),IF(Q11>25000,"発送不可",INDEX('エコノミー送料'!D10:D75,COUNTIF('エコノミー送料'!C10:C75,"<"&Q11)+1))))))} -> 3599 | J16: ='FedEx 送料'!B12 -> 5362 | K16: ='DHL 送料'!B12 -> 4999 | M16: =IF(ISNUMBER(C13),C13-M21,C13) -> -335.59755 | N16: =IF(ISNUMBER(C13),C13-(C4*L4*'設定'!B13+'設定'!B14*B2+'設定'!B15),C13) -> 389.40245 | O16: =IF(ISNUMBER(D13),IF(ISNUMBER(O21),D13-O21,O21),D13) -> 349.62345 | P16: DHL正式通関処理 円 | Q16: =IF(Q3="正式",'設定'!B56,0) -> 0
I17: エコノミー適用重量 | N17: ※CD/DVD/Blu-ray/レコード/書籍/漫画/雑誌/ポスター等 | P17: FedEx US通関費 | Q17: =Q12+'設定'!B48 -> 438
I18: =Q11 -> 1500 | P18: DHL US通関費 | Q18: =SUM(Q13:Q16)+'設定'!B49 -> 1068
M19: 還付込み | N19: 還付込み | O19: EU Zonos 還付込み | P19: FedEx US関税コスト | Q19: =Q7+Q17+ROUND((Q7+Q17)*'設定'!B16,0) -> 1187
A20: 販売後受取額（加算方式） | B20: =IF(NOT(ISNUMBER(B4)),"販売価格未入力",IF(NOT(ISNUMBER(C4)),"仕入価格未入力",IF(B2<=0,"為替未設定",IF(ISNUMBER(E4),(B4+C2)*B2*(1-(E4+G4+H4+I4+IF(J4="On",'設定'!B18,0))),E4)))) -> 10558.218 | M20: =IF(ISNUMBER(M16),M16+B22,M16) -> 191.67518 | N20: =IF(ISNUMBER(N16),N16+B22,N16) -> 916.67518 | O20: =IF(ISNUMBER(O16),O16+B22,O16) -> 876.89618 | P20: DHL US関税コスト | Q20: =Q8+Q18+ROUND((Q8+Q18)*'設定'!B16,0) -> 1831
A21: 販売後受取額（Payoneer後掛け） | B21: =IF(NOT(ISNUMBER(B4)),"販売価格未入力",IF(NOT(ISNUMBER(C4)),"仕入価格未入力",IF(B2<=0,"為替未設定",IF(ISNUMBER(E4),(B4+C2)*(1-(E4+G4+I4+IF(J4="On",'設定'!B18,0)))*(1-H4)*B2,E4)))) -> 10614.159 | M21: =C4*L4*(1+'設定'!B13)+'設定'!B14*B2+'設定'!B15 -> 1367.816 | O21: =IF(AND(ISNUMBER('設定'!B42),'設定'!B42>0),IF(AND(ISNUMBER('設定'!B26),'設定'!B26>=0,ISNUMBER('設定'!B43),'設定'!B43>=0),'設定'!B26+'設定'!B43*'設定'!B42,"EU費用未設定"),"為替取得不可") -> 1348.595 | P21: EU Economy関税コスト | Q21: =IF(ISNUMBER(Q5),Q5+'設定'!B46+ROUND((Q5+'設定'!B46)*'設定'!B16,0),Q5) -> 567
A22: 消費税還付額 | B22: =IF(ISNUMBER(C4),C4/(1+'設定'!B19)*'設定'!B19,"仕入価格未入力") -> 527.27273 | M22: Zonos関税・手数料 | O22: EU Zonos 手数料・関税 | P22: EU FedEx関税コスト | Q22: =IF(ISNUMBER(Q5),Q5+'設定'!C30+ROUND((Q5+'設定'!C30)*'設定'!B16,0),Q5) -> 567
P23: EU DHL税金元払い | Q23: =IF(ISNUMBER(Q5),IF(Q5>0,ROUND(MAX(Q5*'設定'!B59,'設定'!B60),0),0),Q5) -> 850
P24: EU DHL関税コスト | Q24: =IF(ISNUMBER(Q5),Q5+Q23+'設定'!C31+ROUND((Q5+Q23+'設定'!C31)*'設定'!B16,0),Q5) -> 1435
P25: EU Economy利益 | Q25: =IF(ISNUMBER('エコノミー送料'!G5),IF(ISNUMBER(B20),B20-C4-'エコノミー送料'!G5,B20),'エコノミー送料'!G5) -> -1440.7815
P26: EU Economy還付込み | Q26: =IF(ISNUMBER(Q25),Q25+B22,Q25) -> -913.50882
P27: EU FedEx利益 | Q27: =IF(ISNUMBER(IF(ISNUMBER('設定'!B30),'設定'!B30,'FedEx 送料'!M3)),IF(ISNUMBER(Q22),IF(ISNUMBER(B20),B20-C4-IF(ISNUMBER('設定'!B30),'設定'!B30,'FedEx 送料'!M3)-Q22,B20),Q22),'FedEx 送料'!M3) -> -892.78155
P28: EU FedEx還付込み | Q28: =IF(ISNUMBER(Q27),Q27+B22,Q27) -> -365.50882
P29: EU DHL利益 | Q29: =IF(ISNUMBER(IF(ISNUMBER('設定'!B31),'設定'!B31,'DHL 送料'!M6)),IF(ISNUMBER(Q24),IF(ISNUMBER(B20),B20-C4-IF(ISNUMBER('設定'!B31),'設定'!B31,'DHL 送料'!M6)-Q24,B20),Q24),'DHL 送料'!M6) -> -2209.7815
P30: EU DHL還付込み | Q30: =IF(ISNUMBER(Q29),Q29+B22,Q29) -> -1682.5088

Sheet 設定
A2: 料金・手数料の設定
A4: USD/JPY | B4: =IFERROR(__xludf.DUMMYFUNCTION("IFERROR(GOOGLEFINANCE(""CURRENCY:USDJPY""),158.4355)"),158.15800000000002) -> 158.158 | D4: Googleスプレッドシートでドル円を自動取得。取得失敗時は元ファイルの保存値を使用。
A5: 海外決済手数料 | B5: 0.0135 | D5: 元表の設定
A6: Payoneer手数料 | B6: 0.025 | D6: 元表の設定
A7: 広告料率（PL） | B7: 0 | D7: 元表の設定
A8: 手数料の追加3% | B8: On | D8: 元表のOn／Off切替
A9: 日本郵便 切手割引 | B9: 0.1 | D9: 日本郵便送料に適用
A10: US 関税率 | B10: 0.125 | D10: US見積率。関税額の個別上書きは下段。
A11: FedEx US MPF（USD・簡易） | B11: 2.77 | D11: FedEx資料40頁：2.77 USD。実際の請求額で変更可。
A13: Zonos 関税処理率 | B13: 0.1 | D13: 元式：仕入価格×関税率×(1＋10%)
A14: Zonos 固定手数料（USD） | B14: 2 | D14: 元式の定数
A15: Zonos 固定費（円） | B15: 254 | D15: 元式の定数
A16: CPaSS 関税処理率 | B16: 0.021 | D16: 関税・税金・対象通関費の合計に掛ける処理率。
A17: CPaSS Economy 固定費（円） | B17: 245 | D17: Economy US輸入通関手数料。
A18: 追加手数料率 | B18: 0.03 | D18: 追加3%がOnのとき適用
A19: 仕入 消費税率 | B19: 0.1 | D19: 税込仕入価格から還付額を計算
A20: 体積重量A 除数（cm³/kg） | B20: 8000 | D20: Economy：長さ×幅×高さ÷8,000 kg。計算内部は×1,000でg換算。
A21: 体積重量B 除数（cm³/kg） | B21: 5000 | D21: FedEx/DHL：長さ×幅×高さ÷5,000 kg。FedExは各辺を整数cmへ切上げ。
A23: CPaSS Economy サーチャージ | B23: ='エコノミー送料'!G11 -> 0.145 | D23: 「エコノミー送料」G11を直接変更。2026-10-01発効14.5%。
A25: EU Zonos 送料（円） | B25: ='計算詳細'!D16 -> 3060 | D25: EUエアパケの重量別送料。日本郵便の切手割引設定も適用。
A26: EU Zonos 固定手数料（円） | B26: 818 | D26: ユーザー確認値：1配送につき818円。US Zonosの手数料とは別設定。
A27: EU配送先 | B27: イタリア | D27: EU27か国から選択。3配送の送料が連動。
A28: EU関税（1分類・円） | B28: 555 | D28: 3マニュアルのEU欄：555円／関税分類。
A29: EU送料の上書き（B列）・追加通関費（C列）
A30: EU FedEx | C30: 0 | D30: B列空欄で自動送料。C列は追加税金・通関費。
A31: EU DHL | C31: 0 | D31: B列空欄で自動送料。C列は追加税金・通関費。
A33: 計算の内訳（確認用）
A34: 適用eBay手数料 | B34: ='計算詳細'!E4 -> 0.127
A35: CPaSS Economy 関税等 | B35: ='計算詳細'!I8 -> 985
A36: FedEx US関税等 | B36: ='計算詳細'!Q19 -> 1187
A37: DHL US関税等 | B37: ='計算詳細'!Q20 -> 1831
A38: Zonos 関税・手数料合計 | B38: ='計算詳細'!M21 -> 1367.816
A39: 仕入 消費税還付額 | B39: ='計算詳細'!B22 -> 527.27273
A41: 料金表の出典 | D41: Economy：2026-07-30版。FedEx・DHL：2026-10-01版。各送料ページに出典。
A42: EUR/JPY | B42: =IFERROR(__xludf.DUMMYFUNCTION("IFERROR(GOOGLEFINANCE(""CURRENCY:EURJPY""),B44)"),176.865) -> 176.865 | D42: Googleスプレッドシートでは自動取得。Excel・取得失敗時はB44の参考値を使うため自動更新されません。
A43: EU Zonos 関税（EUR） | B43: 3 | D43: ユーザー確認値：1配送につき3ユーロ。B42の円レートを掛けて控除。
A44: EUR/JPY 参考値（Excel用） | B44: 178.15 | D44: 2026-10-06 ECB参考値。https://www.ecb.europa.eu/stats/policy_and_exchange_rates/euro_reference_exchange_rates/html/index.nl.html
A45: EU関税分類数 | B45: 1 | D45: 1種類なら1。同じ分類の数量ではなく、分類の種類数。
A46: EU Economy追加通関費（円） | B46: 0 | D46: 追加税金・通関費があれば入力。
A47: US Economy関税額上書き（円） | D47: 空欄なら仕入価格×US関税率。0円も上書き可。
...

Sheet 使い方
A2: 使い方
A4: 通常の入力 | B4: 「計算式」上段の黄色セルに販売価格（USD）、仕入価格（税込・円）、実重量（g）を入力。カテゴリNoは必要なときだけ変更。
A5: 購入者負担送料 | B5: 販売価格とは別に受け取る送料は「購入者送料（USD）」へ入力。送料無料なら0。
A6: 梱包サイズ | B6: FedEx／DHLの比較には長さ・幅・高さ（cm）を入力。長さは最長辺。
A7: US Zonos | B7: 送料はエアパケットUSの日本郵便送料。利益は元表の関税・Zonos費用を控除した金額。
A8: EU Zonos／CPaSS | B8: EU Zonos＝EUエアパケ利益－818円－3ユーロ×EUR/JPY。EU Economyは設定B27の配送先に連動。
A9: EU FedEx／DHL | B9: EU国を「設定」B27で選択。FedEx・DHLも同じ国で計算。送料上書きは設定B30/B31（空欄で自動）。
A10: 還付込み | B10: 利益＋税込仕入価格÷1.1×10%。仕入6,000円なら約545円を加算。実際の還付の可否判定は行いません。
A11: 料率の変更 | B11: 「設定」で海外決済手数料、Payoneer、広告、追加3%、切手割引、関税、MPF、Zonos等を変更。
A12: 為替 | B12: 元表はGoogle Financeの式をExcelへ書き出した際の固定値158.4355を保存。「設定」B4は手入力。
A13: Google Sheetsの為替 | B13: Googleスプレッドシートでは、設定B4でUSD/JPY、B42でEUR/JPYをGOOGLEFINANCEから自動取得。取得失敗時やExcelでは保存済みの参考値を使用。
A14: カテゴリー | B14: 元のカテゴリー手数料一覧・価格別料率を継承。未登録Noは利益欄に「カテゴリ未登録」を表示。
A15: 送料表 | B15: EconomyはeBay用2026-07-30版、FedEx FICP・DHL荷物用は2026-10-01版のUS/EU基本送料を使用。
... A28: 確定請求 | B28: 各費用は円単位へ四捨五入した見積額。最終利益は配送会社の確定請求額に合わせて関税・追加費用・送料を上書き。
